Traceback (most recent call last):
  File "/Users/cmosquerat/Documents/GitHub/GCPDSBooks/gcpds/lib/python3.11/site-packages/jupyter_cache/executors/utils.py", line 58, in single_nb_execution
    executenb(
  File "/Users/cmosquerat/Documents/GitHub/GCPDSBooks/gcpds/lib/python3.11/site-packages/nbclient/client.py", line 1305, in execute
    return NotebookClient(nb=nb, resources=resources, km=km, **kwargs).execute()
           ^^^^^^^^^^^^^^^^^^^^^^^^^^^^^^^^^^^^^^^^^^^^^^^^^^^^^^^^^^^^^^^^^^^^^
  File "/Users/cmosquerat/Documents/GitHub/GCPDSBooks/gcpds/lib/python3.11/site-packages/jupyter_core/utils/__init__.py", line 166, in wrapped
    return loop.run_until_complete(inner)
           ^^^^^^^^^^^^^^^^^^^^^^^^^^^^^^
  File "/opt/homebrew/Cellar/python@3.11/3.11.5/Frameworks/Python.framework/Versions/3.11/lib/python3.11/asyncio/base_events.py", line 653, in run_until_complete
    return future.result()
           ^^^^^^^^^^^^^^^
  File "/Users/cmosquerat/Documents/GitHub/GCPDSBooks/gcpds/lib/python3.11/site-packages/nbclient/client.py", line 705, in async_execute
    await self.async_execute_cell(
  File "/Users/cmosquerat/Documents/GitHub/GCPDSBooks/gcpds/lib/python3.11/site-packages/nbclient/client.py", line 1058, in async_execute_cell
    await self._check_raise_for_error(cell, cell_index, exec_reply)
  File "/Users/cmosquerat/Documents/GitHub/GCPDSBooks/gcpds/lib/python3.11/site-packages/nbclient/client.py", line 914, in _check_raise_for_error
    raise CellExecutionError.from_cell_and_msg(cell, exec_reply_content)
nbclient.exceptions.CellExecutionError: An error occurred while executing the following cell:
------------------
import warnings
warnings.filterwarnings('ignore')

from tensorflow.keras.models import Model
from tensorflow.keras.layers import Input, Dense

import tensorflow as tf
tf.logging.set_verbosity(tf.logging.ERROR)

#plotting
import matplotlib.pyplot as plt
%matplotlib inline

#dataset
from tensorflow.keras.datasets import mnist
import numpy as np
------------------


[0;31m---------------------------------------------------------------------------[0m
[0;31mAttributeError[0m                            Traceback (most recent call last)
Cell [0;32mIn[1], line 8[0m
[1;32m      5[0m [38;5;28;01mfrom[39;00m [38;5;21;01mtensorflow[39;00m[38;5;21;01m.[39;00m[38;5;21;01mkeras[39;00m[38;5;21;01m.[39;00m[38;5;21;01mlayers[39;00m [38;5;28;01mimport[39;00m Input, Dense
[1;32m      7[0m [38;5;28;01mimport[39;00m [38;5;21;01mtensorflow[39;00m [38;5;28;01mas[39;00m [38;5;21;01mtf[39;00m
[0;32m----> 8[0m [43mtf[49m[38;5;241;43m.[39;49m[43mlogging[49m[38;5;241m.[39mset_verbosity(tf[38;5;241m.[39mlogging[38;5;241m.[39mERROR)
[1;32m     10[0m [38;5;66;03m#plotting[39;00m
[1;32m     11[0m [38;5;28;01mimport[39;00m [38;5;21;01mmatplotlib[39;00m[38;5;21;01m.[39;00m[38;5;21;01mpyplot[39;00m [38;5;28;01mas[39;00m [38;5;21;01mplt[39;00m

[0;31mAttributeError[0m: module 'tensorflow' has no attribute 'logging'

